Workbook

Sheet Sheet1
A1: Transect # | B1: Segment | C1: Family | D1: Genus | E1: Epithet | F1: Species | G1: Species common | H1: Raw name | I1: StartLattitude | J1: StartLongitude | K1: EndLattitude | L1: EndLongitude | M1: BurnDate | N1: CollectedDate | O1: Time Category | P1: Category symbol | Q1: Burn Unit | R1: Days Since Burn | S1: Notes | T1: Cleaning notes
A2: 1 | B2: 1 | C2: =_xlfn.XLOOKUP(Table1[[#This Row],[Genus]],'Flora of PA'!J:J,'Flora of PA'!D:D) -> Ericaceae | D2: Gaylussacia | E2: baccata | F2: =Table1[[#This Row],[Genus]]&" "&Table1[[#This Row],[Epithet]] -> Gaylussacia baccata | G2: black huckleberry | H2: Huck | I2: 41.43963 | J2: -75.54115 | K2: 41.44045 | L2: -75.54094 | M2: 10/20/2015 | N2: 6/12/2026 | O2: 10+ | P2: D | Q2: Preserve 10+
A3: 1 | B3: 1 | C3: =_xlfn.XLOOKUP(Table1[[#This Row],[Genus]],'Flora of PA'!J:J,'Flora of PA'!D:D) -> Poaceae | D3: Schizachyrium | E3: scoparium | F3: =Table1[[#This Row],[Genus]]&" "&Table1[[#This Row],[Epithet]] -> Schizachyrium scoparium | G3: little bluestem | H3: Little bluestem | I3: 41.43963 | J3: -75.54115 | K3: 41.44045 | L3: -75.54094 | M3: 10/20/2015 | N3: 6/13/2026 | O3: 10+ | P3: D | Q3: Preserve 10+
A4: 1 | B4: 1 | C4: =_xlfn.XLOOKUP(Table1[[#This Row],[Genus]],'Flora of PA'!J:J,'Flora of PA'!D:D) -> Betulaceae | D4: Betula | E4: populifolia | F4: =Table1[[#This Row],[Genus]]&" "&Table1[[#This Row],[Epithet]] -> Betula populifolia | G4: gray birch | H4: Gray birch | I4: 41.43963 | J4: -75.54115 | K4: 41.44045 | L4: -75.54094 | M4: 10/20/2015 | N4: 6/13/2026 | O4: 10+ | P4: D | Q4: Preserve 10+
A5: 1 | B5: 1 | C5: =_xlfn.XLOOKUP(Table1[[#This Row],[Genus]],'Flora of PA'!J:J,'Flora of PA'!D:D) -> Asteraceae | D5: Solidago | E5: rugosa | F5: =Table1[[#This Row],[Genus]]&" "&Table1[[#This Row],[Epithet]] -> Solidago rugosa | G5: wrinkleleaf goldenrod | H5: Solidago rigosa | I5: 41.43963 | J5: -75.54115 | K5: 41.44045 | L5: -75.54094 | M5: 10/20/2015 | N5: 6/13/2026 | O5: 10+ | P5: D | Q5: Preserve 10+
A6: 1 | B6: 1 | C6: =_xlfn.XLOOKUP(Table1[[#This Row],[Genus]],'Flora of PA'!J:J,'Flora of PA'!D:D) -> Asteraceae | D6: Euthamia | E6: graminifolia | F6: =Table1[[#This Row],[Genus]]&" "&Table1[[#This Row],[Epithet]] -> Euthamia graminifolia | G6: grass leaved goldentop | H6: Grass leaves goldenrod | I6: 41.43963 | J6: -75.54115 | K6: 41.44045 | L6: -75.54094 | M6: 10/20/2015 | N6: 6/13/2026 | O6: 10+ | P6: D | Q6: Preserve 10+
A7: 1 | B7: 1 | C7: =_xlfn.XLOOKUP(Table1[[#This Row],[Genus]],'Flora of PA'!J:J,'Flora of PA'!D:D) -> Salicaceae | D7: Populus | E7: tremuloides | F7: =Table1[[#This Row],[Genus]]&" "&Table1[[#This Row],[Epithet]] -> Populus tremuloides | G7: quaking aspen | H7: Quaking aspen | I7: 41.43963 | J7: -75.54115 | K7: 41.44045 | L7: -75.54094 | M7: 10/20/2015 | N7: 6/13/2026 | O7: 10+ | P7: D | Q7: Preserve 10+
A8: 1 | B8: 1 | C8: =_xlfn.XLOOKUP(Table1[[#This Row],[Genus]],'Flora of PA'!J:J,'Flora of PA'!D:D) -> Rosaceae | D8: Rubus | E8: hispidus | F8: =Table1[[#This Row],[Genus]]&" "&Table1[[#This Row],[Epithet]] -> Rubus hispidus | G8: bristly dewberry | H8: Dewberry | I8: 41.43963 | J8: -75.54115 | K8: 41.44045 | L8: -75.54094 | M8: 10/20/2015 | N8: 6/13/2026 | O8: 10+ | P8: D | Q8: Preserve 10+
A9: 1 | B9: 1 | C9: =_xlfn.XLOOKUP(Table1[[#This Row],[Genus]],'Flora of PA'!J:J,'Flora of PA'!D:D) -> Poaceae | D9: Danthonia | E9: spicata | F9: =Table1[[#This Row],[Genus]]&" "&Table1[[#This Row],[Epithet]] -> Danthonia spicata | G9: poverty oatgrass | H9: Poverty oatgrass? | I9: 41.43963 | J9: -75.54115 | K9: 41.44045 | L9: -75.54094 | M9: 10/20/2015 | N9: 6/13/2026 | O9: 10+ | P9: D | Q9: Preserve 10+
A10: 1 | B10: 1 | C10: =_xlfn.XLOOKUP(Table1[[#This Row],[Genus]],'Flora of PA'!J:J,'Flora of PA'!D:D) -> Pinaceae | D10: Pinus | E10: rigida | F10: =Table1[[#This Row],[Genus]]&" "&Table1[[#This Row],[Epithet]] -> Pinus rigida | G10: pitch pine | H10: Pitch pine | I10: 41.43963 | J10: -75.54115 | K10: 41.44045 | L10: -75.54094 | M10: 10/20/2015 | N10: 6/13/2026 | O10: 10+ | P10: D | Q10: Preserve 10+
A11: 1 | B11: 2 | C11: =_xlfn.XLOOKUP(Table1[[#This Row],[Genus]],'Flora of PA'!J:J,'Flora of PA'!D:D) -> Rosaceae | D11: Rubus | E11: hispidus | F11: =Table1[[#This Row],[Genus]]&" "&Table1[[#This Row],[Epithet]] -> Rubus hispidus | G11: bristly dewberry | H11: Dewberry | I11: 41.43963 | J11: -75.54115 | K11: 41.44045 | L11: -75.54094 | M11: 10/20/2015 | N11: 6/13/2026 | O11: 10+ | P11: D | Q11: Preserve 10+
A12: 1 | B12: 2 | C12: =_xlfn.XLOOKUP(Table1[[#This Row],[Genus]],'Flora of PA'!J:J,'Flora of PA'!D:D) -> Polypodiaceae | D12: Pteridium | E12: aquilinum | F12: =Table1[[#This Row],[Genus]]&" "&Table1[[#This Row],[Epithet]] -> Pteridium aquilinum | G12: bracken fern | H12: Bracken fern | I12: 41.43963 | J12: -75.54115 | K12: 41.44045 | L12: -75.54094 | M12: 10/20/2015 | N12: 6/13/2026 | O12: 10+ | P12: D | Q12: Preserve 10+
A13: 1 | B13: 2 | C13: =_xlfn.XLOOKUP(Table1[[#This Row],[Genus]],'Flora of PA'!J:J,'Flora of PA'!D:D) -> Cyperaceae | D13: Carex | E13: blanda | F13: =Table1[[#This Row],[Genus]]&" "&Table1[[#This Row],[Epithet]] -> Carex blanda | G13: eastern woodland sedge | H13: The not limestone meadow sedge | I13: 41.43963 | J13: -75.54115 | K13: 41.44045 | L13: -75.54094 | M13: 10/20/2015 | N13: 6/13/2026 | O13: 10+ | P13: D | Q13: Preserve 10+ | S13: add species name
A14: 1 | B14: 2 | C14: =_xlfn.XLOOKUP(Table1[[#This Row],[Genus]],'Flora of PA'!J:J,'Flora of PA'!D:D) -> Poaceae | D14: Andropogon | E14: gerardi | F14: =Table1[[#This Row],[Genus]]&" "&Table1[[#This Row],[Epithet]] -> Andropogon gerardi | G14: big bluestem | H14: Big bluestem | I14: 41.43963 | J14: -75.54115 | K14: 41.44045 | L14: -75.54094 | M14: 10/20/2015 | N14: 6/13/2026 | O14: 10+ | P14: D | Q14: Preserve 10+
A15: 1 | B15: 2 | C15: =_xlfn.XLOOKUP(Table1[[#This Row],[Genus]],'Flora of PA'!J:J,'Flora of PA'!D:D) -> Asteraceae | D15: Hieracium | E15: scabrum | F15: =Table1[[#This Row],[Genus]]&" "&Table1[[#This Row],[Epithet]] -> Hieracium scabrum | G15: hawkeed | H15: Hairy hawkweed | I15: 41.43963 | J15: -75.54115 | K15: 41.44045 | L15: -75.54094 | M15: 10/20/2015 | N15: 6/13/2026 | O15: 10+ | P15: D | Q15: Preserve 10+ | S15: actually rough hawkweed
A16: 1 | B16: 2 | C16: =_xlfn.XLOOKUP(Table1[[#This Row],[Genus]],'Flora of PA'!J:J,'Flora of PA'!D:D) -> Poaceae | D16: Danthonia | E16: spicata | F16: =Table1[[#This Row],[Genus]]&" "&Table1[[#This Row],[Epithet]] -> Danthonia spicata | G16: poverty oatgrass | H16: Poverty oatgrass | I16: 41.43963 | J16: -75.54115 | K16: 41.44045 | L16: -75.54094 | M16: 10/20/2015 | N16: 6/13/2026 | O16: 10+ | P16: D | Q16: Preserve 10+
A17: 1 | B17: 2 | C17: =_xlfn.XLOOKUP(Table1[[#This Row],[Genus]],'Flora of PA'!J:J,'Flora of PA'!D:D) -> Asteraceae | D17: Solidago | E17: rugosa | F17: =Table1[[#This Row],[Genus]]&" "&Table1[[#This Row],[Epithet]] -> Solidago rugosa | G17: wrinkleleaf goldenrod | H17: S rugosa | I17: 41.43963 | J17: -75.54115 | K17: 41.44045 | L17: -75.54094 | M17: 10/20/2015 | N17: 6/13/2026 | O17: 10+ | P17: D | Q17: Preserve 10+
A18: 1 | B18: 2 | C18: =_xlfn.XLOOKUP(Table1[[#This Row],[Genus]],'Flora of PA'!J:J,'Flora of PA'!D:D) -> Asteraceae | D18: Leucanthemum | E18: vulgare | F18: =Table1[[#This Row],[Genus]]&" "&Table1[[#This Row],[Epithet]] -> Leucanthemum vulgare | G18: oxeye daisy | H18: Oxeye daisy | I18: 41.43963 | J18: -75.54115 | K18: 41.44045 | L18: -75.54094 | M18: 10/20/2015 | N18: 6/13/2026 | O18: 10+ | P18: D | Q18: Preserve 10+
A19: 1 | B19: 2 | C19: =_xlfn.XLOOKUP(Table1[[#This Row],[Genus]],'Flora of PA'!J:J,'Flora of PA'!D:D) -> Ericaceae | D19: Gaylussacia | E19: baccata | F19: =Table1[[#This Row],[Genus]]&" "&Table1[[#This Row],[Epithet]] -> Gaylussacia baccata | G19: black huckleberry | H19: Huckleberry | I19: 41.43963 | J19: -75.54115 | K19: 41.44045 | L19: -75.54094 | M19: 10/20/2015 | N19: 6/13/2026 | O19: 10+ | P19: D | Q19: Preserve 10+
A20: 1 | B20: 2 | C20: =_xlfn.XLOOKUP(Table1[[#This Row],[Genus]],'Flora of PA'!J:J,'Flora of PA'!D:D) -> Salicaceae | D20: Populus | E20: tremuloides | F20: =Table1[[#This Row],[Genus]]&" "&Table1[[#This Row],[Epithet]] -> Populus tremuloides | G20: quaking aspen | H20: Quaking aspen | I20: 41.43963 | J20: -75.54115 | K20: 41.44045 | L20: -75.54094 | M20: 10/20/2015 | N20: 6/13/2026 | O20: 10+ | P20: D | Q20: Preserve 10+
A21: 1 | B21: 3 | C21: =_xlfn.XLOOKUP(Table1[[#This Row],[Genus]],'Flora of PA'!J:J,'Flora of PA'!D:D) -> Rosaceae | D21: Rubus | E21: hispidus | F21: =Table1[[#This Row],[Genus]]&" "&Table1[[#This Row],[Epithet]] -> Rubus hispidus | G21: bristly dewberry | H21: Dewberry | I21: 41.43963 | J21: -75.54115 | K21: 41.44045 | L21: -75.54094 | M21: 10/20/2015 | N21: 6/13/2026 | O21: 10+ | P21: D | Q21: Preserve 10+
A22: 1 | B22: 3 | C22: =_xlfn.XLOOKUP(Table1[[#This Row],[Genus]],'Flora of PA'!J:J,'Flora of PA'!D:D) -> Ericaceae | D22: Vaccinium | E22: angustifolium | F22: =Table1[[#This Row],[Genus]]&" "&Table1[[#This Row],[Epithet]] -> Vaccinium angustifolium | G22: lowbush blueberry | H22: Blueberry | I22: 41.43963 | J22: -75.54115 | K22: 41.44045 | L22: -75.54094 | M22: 10/20/2015 | N22: 6/13/2026 | O22: 10+ | P22: D | Q22: Preserve 10+
A23: 1 | B23: 3 | C23: =_xlfn.XLOOKUP(Table1[[#This Row],[Genus]],'Flora of PA'!J:J,'Flora of PA'!D:D) -> Polypodiaceae | D23: Pteridium | E23: aquilinum | F23: =Table1[[#This Row],[Genus]]&" "&Table1[[#This Row],[Epithet]] -> Pteridium aquilinum | G23: bracken fern | H23: Bracken fern | I23: 41.43963 | J23: -75.54115 | K23: 41.44045 | L23: -75.54094 | M23: 10/20/2015 | N23: 6/13/2026 | O23: 10+ | P23: D | Q23: Preserve 10+
A24: 1 | B24: 3 | C24: =_xlfn.XLOOKUP(Table1[[#This Row],[Genus]],'Flora of PA'!J:J,'Flora of PA'!D:D) -> Asteraceae | D24: Solidago | E24: rugosa | F24: =Table1[[#This Row],[Genus]]&" "&Table1[[#This Row],[Epithet]] -> Solidago rugosa | G24: wrinkleleaf goldenrod | H24: S rugosa | I24: 41.43963 | J24: -75.54115 | K24: 41.44045 | L24: -75.54094 | M24: 10/20/2015 | N24: 6/13/2026 | O24: 10+ | P24: D | Q24: Preserve 10+
A25: 1 | B25: 3 | C25: =_xlfn.XLOOKUP(Table1[[#This Row],[Genus]],'Flora of PA'!J:J,'Flora of PA'!D:D) -> Fagaceae | D25: Quercus | E25: ilicifolia | F25: =Table1[[#This Row],[Genus]]&" "&Table1[[#This Row],[Epithet]] -> Quercus ilicifolia | G25: scrub oak | H25: Scrub oak | I25: 41.43963 | J25: -75.54115 | K25: 41.44045 | L25: -75.54094 | M25: 10/20/2015 | N25: 6/13/2026 | O25: 10+ | P25: D | Q25: Preserve 10+
A26: 1 | B26: 3 | C26: =_xlfn.XLOOKUP(Table1[[#This Row],[Genus]],'Flora of PA'!J:J,'Flora of PA'!D:D) -> Ericaceae | D26: Gaylussacia | E26: baccata | F26: =Table1[[#This Row],[Genus]]&" "&Table1[[#This Row],[Epithet]] -> Gaylussacia baccata | G26: black huckleberry | H26: Huckleberry | I26: 41.43963 | J26: -75.54115 | K26: 41.44045 | L26: -75.54094 | M26: 10/20/2015 | N26: 6/13/2026 | O26: 10+ | P26: D | Q26: Preserve 10+
A27: 1 | B27: 3 | C27: =_xlfn.XLOOKUP(Table1[[#This Row],[Genus]],'Flora of PA'!J:J,'Flora of PA'!D:D) -> Cyperaceae | D27: Carex | E27: blanda | F27: =Table1[[#This Row],[Genus]]&" "&Table1[[#This Row],[Epithet]] -> Carex blanda | G27: eastern woodland sedge | H27: Not limestone meadow | I27: 41.43963 | J27: -75.54115 | K27: 41.44045 | L27: -75.54094 | M27: 10/20/2015 | N27: 6/13/2026 | O27: 10+ | P27: D | Q27: Preserve 10+ | S27: add species name
A28: 1 | B28: 3 | C28: =_xlfn.XLOOKUP(Table1[[#This Row],[Genus]],'Flora of PA'!J:J,'Flora of PA'!D:D) -> Asteraceae | D28: Hieracium | E28: scabrum | F28: =Table1[[#This Row],[Genus]]&" "&Table1[[#This Row],[Epithet]] -> Hieracium scabrum | G28: rough hawkweed | H28: Rough hawkweed | I28: 41.43963 | J28: -75.54115 | K28: 41.44045 | L28: -75.54094 | M28: 10/20/2015 | N28: 6/13/2026 | O28: 10+ | P28: D | Q28: Preserve 10+
A29: 1 | B29: 3 | C29: =_xlfn.XLOOKUP(Table1[[#This Row],[Genus]],'Flora of PA'!J:J,'Flora of PA'!D:D) -> Salicaceae | D29: Populus | E29: tremuloides | F29: =Table1[[#This Row],[Genus]]&" "&Table1[[#This Row],[Epithet]] -> Populus tremuloides | G29: quaking aspen | H29: Quaking aspen | I29: 41.43963 | J29: -75.54115 | K29: 41.44045 | L29: -75.54094 | M29: 10/20/2015 | N29: 6/13/2026 | O29: 10+ | P29: D | Q29: Preserve 10+
A30: 1 | B30: 3 | C30: =_xlfn.XLOOKUP(Table1[[#This Row],[Genus]],'Flora of PA'!J:J,'Flora of PA'!D:D) -> Asteraceae | D30: Leucanthemum | E30: vulgare | F30: =Table1[[#This Row],[Genus]]&" "&Table1[[#This Row],[Epithet]] -> Leucanthemum vulgare | G30: oxeye daisy | H30: Oxeye daisy | I30: 41.43963 | J30: -75.54115 | K30: 41.44045 | L30: -75.54094 | M30: 10/20/2015 | N30: 6/13/2026 | O30: 10+ | P30: D | Q30: Preserve 10+
A31: 1 | B31: 4 | C31: =_xlfn.XLOOKUP(Table1[[#This Row],[Genus]],'Flora of PA'!J:J,'Flora of PA'!D:D) -> Cyperaceae | D31: Carex | E31: intumescens | F31: =Table1[[#This Row],[Genus]]&" "&Table1[[#This Row],[Epithet]] -> Carex intumescens | G31: bladder sedge | H31: Bladder sedge | I31: 41.43963 | J31: -75.54115 | K31: 41.44045 | L31: -75.54094 | M31: 10/20/2015 | N31: 6/13/2026 | O31: 10+ | P31: D | Q31: Preserve 10+
A32: 1 | B32: 4 | C32: =_xlfn.XLOOKUP(Table1[[#This Row],[Genus]],'Flora of PA'!J:J,'Flora of PA'!D:D) -> Rosaceae | D32: Rubus | E32: hispidus | F32: =Table1[[#This Row],[Genus]]&" "&Table1[[#This Row],[Epithet]] -> Rubus hispidus | G32: bristly dewberry | H32: Dewberry | I32: 41.43963 | J32: -75.54115 | K32: 41.44045 | L32: -75.54094 | M32: 10/20/2015 | N32: 6/13/2026 | O32: 10+ | P32: D | Q32: Preserve 10+
A33: 1 | B33: 4 | C33: =_xlfn.XLOOKUP(Table1[[#This Row],[Genus]],'Flora of PA'!J:J,'Flora of PA'!D:D) -> Ericaceae | D33: Gaylussacia | E33: baccata | F33: =Table1[[#This Row],[Genus]]&" "&Table1[[#This Row],[Epithet]] -> Gaylussacia baccata | G33: black huckleberry | H33: Huckleberry | I33: 41.43963 | J33: -75.54115 | K33: 41.44045 | L33: -75.54094 | M33: 10/20/2015 | N33: 6/13/2026 | O33: 10+ | P33: D | Q33: Preserve 10+
A34: 1 | B34: 4 | C34: =_xlfn.XLOOKUP(Table1[[#This Row],[Genus]],'Flora of PA'!J:J,'Flora of PA'!D:D) -> Poaceae | D34: Andropogon | E34: gerardi | F34: =Table1[[#This Row],[Genus]]&" "&Table1[[#This Row],[Epithet]] -> Andropogon gerardi | G34: big bluestem | H34: Tall bluestem | I34: 41.43963 | J34: -75.54115 | K34: 41.44045 | L34: -75.54094 | M34: 10/20/2015 | N34: 6/13/2026 | O34: 10+ | P34: D | Q34: Preserve 10+
A35: 1 | B35: 4 | C35: =_xlfn.XLOOKUP(Table1[[#This Row],[Genus]],'Flora of PA'!J:J,'Flora of PA'!D:D) -> Sapindaceae | D35: Acer | E35: rubrum | F35: =Table1[[#This Row],[Genus]]&" "&Table1[[#This Row],[Epithet]] -> Acer rubrum | G35: red maple | H35: Red maple | I35: 41.43963 | J35: -75.54115 | K35: 41.44045 | L35: -75.54094 | M35: 10/20/2015 | N35: 6/13/2026 | O35: 10+ | P35: D | Q35: Preserve 10+
A36: 1 | B36: 4 | C36: =_xlfn.XLOOKUP(Table1[[#This Row],[Genus]],'Flora of PA'!J:J,'Flora of PA'!D:D) -> Asteraceae | D36: Hieracium | E36: scabrum | F36: =Table1[[#This Row],[Genus]]&" "&Table1[[#This Row],[Epithet]] -> Hieracium scabrum | G36: rough hawkweed | H36: Rough hawkweed | I36: 41.43963 | J36: -75.54115 | K36: 41.44045 | L36: -75.54094 | M36: 10/20/2015 | N36: 6/13/2026 | O36: 10+ | P36: D | Q36: Preserve 10+
A37: 1 | B37: 4 | C37: =_xlfn.XLOOKUP(Table1[[#This Row],[Genus]],'Flora of PA'!J:J,'Flora of PA'!D:D) -> Poaceae | D37: Schizachyrium | E37: scoparium | F37: =Table1[[#This Row],[Genus]]&" "&Table1[[#This Row],[Epithet]] -> Schizachyrium scoparium | G37: little bluestem | H37: little bluestem | I37: 41.43963 | J37: -75.54115 | K37: 41.44045 | L37: -75.54094 | M37: 10/20/2015 | N37: 6/13/2026 | O37: 10+ | P37: D | Q37: Preserve 10+
A38: 1 | B38: 4 | C38: =_xlfn.XLOOKUP(Table1[[#This Row],[Genus]],'Flora of PA'!J:J,'Flora of PA'!D:D) -> Ericaceae | D38: Kalmia | E38: angustifolia | F38: =Table1[[#This Row],[Genus]]&" "&Table1[[#This Row],[Epithet]] -> Kalmia angustifolia | G38: sheep laurel | H38: Sheep laurel | I38: 41.43963 | J38: -75.54115 | K38: 41.44045 | L38: -75.54094 | M38: 10/20/2015 | N38: 6/13/2026 | O38: 10+ | P38: D | Q38: Preserve 10+
A39: 1 | B39: 4 | C39: =_xlfn.XLOOKUP(Table1[[#This Row],[Genus]],'Flora of PA'!J:J,'Flora of PA'!D:D) -> Pinaceae | D39: Pinus | E39: rigida | F39: =Table1[[#This Row],[Genus]]&" "&Table1[[#This Row],[Epithet]] -> Pinus rigida | G39: pitch pine | H39: Pitch pine | I39: 41.43963 | J39: -75.54115 | K39: 41.44045 | L39: -75.54094 | M39: 10/20/2015 | N39: 6/13/2026 | O39: 10+ | P39: D | Q39: Preserve 10+
... A106: 1 | B106: 10 | C106: =_xlfn.XLOOKUP(Table1[[#This Row],[Genus]],'Flora of PA'!J:J,'Flora of PA'!D:D) -> Fagaceae | D106: Quercus | E106: ilicifolia | F106: =Table1[[#This Row],[Genus]]&" "&Table1[[#This Row],[Epithet]] -> Quercus ilicifolia | G106: scrub oak | H106: Scrub oak | I106: 41.43963 | J106: -75.54115 | K106: 41.44045 | L106: -75.54094 | M106: 10/20/2015 | N106: 6/13/2026 | O106: 10+ | P106: D | Q106: Preserve 10+
...

Sheet notes and translation
A1: translation
A2: segment #'s | B2: 0-10 = 1 | C2: 10-20 =2 | D2: so on
A3: Raw Name | B3: The exact way it is written in the field notes
A4: Catergory symbols | B4: 0-1 | C4: A
B5: 1-5 | C5: B
B6: 5-10 | C6: C
B7: 10+ | C7: D
B8: Never | C8: E
A12: cleaning notes | B12: relized my shining clubmoss is really some hairmoss, needed to change ids
B13: for species only ID down to family level species will be labled as "(family name) sp."
B14: for the two mosses with no greater id than as a moss it will be just Moss sp., same for faimly will just be moss
B15: anything without an extra lower level id will be something different than something else seen before

Sheet Removed entries
A1: 4 | B1: 10 | E1: Reindeer moss morpho | F1: Reindeer moss morpho | G1: 41.44393 | H1: -75.54698 | I1: NA | J1: NA | K1: 10/20/2015 | L1: 6/13/2026 | M1: 10+ | N1: Preserve 10+ | P1: double check for species | Q1: removed as this is a lichen
A6: Transect # | B6: Segment | C6: Genus | D6: Species | E6: Species common | F6: Raw name | G6: StartLattitude | H6: StartLongitude | I6: EndLattitude | J6: EndLongitude | K6: BurnDate | L6: CollectedDate | M6: Time Category | N6: Burn Unit | O6: Days Since Burn | P6: Notes | Q6: Cleaning notes
A7: 22 | B7: 1 | E7: black huckleberry | F7: Huck | G7: 41.49095 | H7: -75.48082 | I7: 41.4904 | J7: -75.48111 | K7: 5/7/2024 | L7: 7/12/2026 | M7: ? | N7: 300 test 1 | P7: seems to have burned more recently than map says must confirm for all in unit | Q7: Removed, not in a relevant unit
A8: 22 | B8: 1 | E8: scrub oak | F8: scrub oak | G8: 41.49095 | H8: -75.48082 | I8: 41.4904 | J8: -75.48111 | K8: 5/7/2024 | L8: 7/12/2026 | M8: ? | N8: 300 test 1 | Q8: Removed, not in a relevant unit
A9: 22 | B9: 1 | E9: bracken fern | F9: Bracken fern | G9: 41.49095 | H9: -75.48082 | I9: 41.4904 | J9: -75.48111 | K9: 5/7/2024 | L9: 7/12/2026 | M9: ? | N9: 300 test 1 | Q9: Removed, not in a relevant unit
A10: 22 | B10: 1 | E10: black chokeberry | F10: Choke berry | G10: 41.49095 | H10: -75.48082 | I10: 41.4904 | J10: -75.48111 | K10: 5/7/2024 | L10: 7/12/2026 | M10: ? | N10: 300 test 1 | Q10: Removed, not in a relevant unit
A11: 22 | B11: 1 | E11: smooth witherod | F11: Viburnum | G11: 41.49095 | H11: -75.48082 | I11: 41.4904 | J11: -75.48111 | K11: 5/7/2024 | L11: 7/12/2026 | M11: ? | N11: 300 test 1 | Q11: Removed, not in a relevant unit
A12: 22 | B12: 2 | E12: bracken fern | F12: Bracken | G12: 41.49095 | H12: -75.48082 | I12: 41.4904 | J12: -75.48111 | K12: 5/7/2024 | L12: 7/12/2026 | M12: ? | N12: 300 test 1 | Q12: Removed, not in a relevant unit
A13: 22 | B13: 2 | E13: black huckleberry | F13: Huck | G13: 41.49095 | H13: -75.48082 | I13: 41.4904 | J13: -75.48111 | K13: 5/7/2024 | L13: 7/12/2026 | M13: ? | N13: 300 test 1 | Q13: Removed, not in a relevant unit
A14: 22 | B14: 2 | E14: scrub oak | F14: Scrub oak | G14: 41.49095 | H14: -75.48082 | I14: 41.4904 | J14: -75.48111 | K14: 5/7/2024 | L14: 7/12/2026 | M14: ? | N14: 300 test 1 | Q14: Removed, not in a relevant unit
A15: 22 | B15: 3 | E15: bracken fern | F15: Bracken | G15: 41.49095 | H15: -75.48082 | I15: 41.4904 | J15: -75.48111 | K15: 5/7/2024 | L15: 7/12/2026 | M15: ? | N15: 300 test 1 | Q15: Removed, not in a relevant unit
A16: 22 | B16: 3 | E16: black huckleberry | F16: Huck | G16: 41.49095 | H16: -75.48082 | I16: 41.4904 | J16: -75.48111 | K16: 5/7/2024 | L16: 7/12/2026 | M16: ? | N16: 300 test 1 | Q16: Removed, not in a relevant unit
A17: 22 | B17: 3 | E17: scrub oak | F17: Scrub oak | G17: 41.49095 | H17: -75.48082 | I17: 41.4904 | J17: -75.48111 | K17: 5/7/2024 | L17: 7/12/2026 | M17: ? | N17: 300 test 1 | Q17: Removed, not in a relevant unit
A18: 22 | B18: 3 | E18: Poacea species | F18: Grass species | G18: 41.49095 | H18: -75.48082 | I18: 41.4904 | J18: -75.48111 | K18: 5/7/2024 | L18: 7/12/2026 | M18: ? | N18: 300 test 1 | P18: decide on morpho | Q18: Removed, not in a relevant unit
A19: 22 | B19: 4 | E19: bracken fern | F19: Bracken | G19: 41.49095 | H19: -75.48082 | I19: 41.4904 | J19: -75.48111 | K19: 5/7/2024 | L19: 7/12/2026 | M19: ? | N19: 300 test 1 | Q19: Removed, not in a relevant unit
A20: 22 | B20: 4 | E20: black huckleberry | F20: Huck | G20: 41.49095 | H20: -75.48082 | I20: 41.4904 | J20: -75.48111 | K20: 5/7/2024 | L20: 7/12/2026 | M20: ? | N20: 300 test 1 | Q20: Removed, not in a relevant unit
A21: 22 | B21: 4 | E21: scrub oak | F21: Scrub oak | G21: 41.49095 | H21: -75.48082 | I21: 41.4904 | J21: -75.48111 | K21: 5/7/2024 | L21: 7/12/2026 | M21: ? | N21: 300 test 1 | Q21: Removed, not in a relevant unit
A22: 22 | B22: 4 | E22: lowbush blueberry | F22: Lbbb | G22: 41.49095 | H22: -75.48082 | I22: 41.4904 | J22: -75.48111 | K22: 5/7/2024 | L22: 7/12/2026 | M22: ? | N22: 300 test 1 | Q22: Removed, not in a relevant unit
A23: 22 | B23: 4 | E23: Poacea species | F23: Grass species | G23: 41.49095 | H23: -75.48082 | I23: 41.4904 | J23: -75.48111 | K23: 5/7/2024 | L23: 7/12/2026 | M23: ? | N23: 300 test 1 | P23: decide on morpho | Q23: Removed, not in a relevant unit
A24: 22 | B24: 5 | E24: bracken fern | F24: Bracken | G24: 41.49095 | H24: -75.48082 | I24: 41.4904 | J24: -75.48111 | K24: 5/7/2024 | L24: 7/12/2026 | M24: ? | N24: 300 test 1 | Q24: Removed, not in a relevant unit
A25: 22 | B25: 5 | E25: black huckleberry | F25: Huck | G25: 41.49095 | H25: -75.48082 | I25: 41.4904 | J25: -75.48111 | K25: 5/7/2024 | L25: 7/12/2026 | M25: ? | N25: 300 test 1 | Q25: Removed, not in a relevant unit
A26: 22 | B26: 5 | E26: scrub oak | F26: Scrub oak | G26: 41.49095 | H26: -75.48082 | I26: 41.4904 | J26: -75.48111 | K26: 5/7/2024 | L26: 7/12/2026 | M26: ? | N26: 300 test 1 | Q26: Removed, not in a relevant unit
A27: 22 | B27: 5 | E27: sassafras | F27: Sass | G27: 41.49095 | H27: -75.48082 | I27: 41.4904 | J27: -75.48111 | K27: 5/7/2024 | L27: 7/12/2026 | M27: ? | N27: 300 test 1 | Q27: Removed, not in a relevant unit
A28: 22 | B28: 5 | E28: lowbush blueberry | F28: Lbbb | G28: 41.49095 | H28: -75.48082 | I28: 41.4904 | J28: -75.48111 | K28: 5/7/2024 | L28: 7/12/2026 | M28: ? | N28: 300 test 1 | Q28: Removed, not in a relevant unit
A29: 22 | B29: 5 | E29: black chokeberry | F29: Chokeberry | G29: 41.49095 | H29: -75.48082 | I29: 41.4904 | J29: -75.48111 | K29: 5/7/2024 | L29: 7/12/2026 | M29: ? | N29: 300 test 1 | Q29: Removed, not in a relevant unit
A30: 22 | B30: 6 | E30: teaberry | F30: Teaberry | G30: 41.49095 | H30: -75.48082 | I30: 41.4904 | J30: -75.48111 | K30: 5/7/2024 | L30: 7/12/2026 | M30: ? | N30: 300 test 1 | Q30: Removed, not in a relevant unit
A31: 22 | B31: 6 | E31: bracken fern | F31: Bracken | G31: 41.49095 | H31: -75.48082 | I31: 41.4904 | J31: -75.48111 | K31: 5/7/2024 | L31: 7/12/2026 | M31: ? | N31: 300 test 1 | Q31: Removed, not in a relevant unit
A32: 22 | B32: 6 | E32: black huckleberry | F32: Huck | G32: 41.49095 | H32: -75.48082 | I32: 41.4904 | J32: -75.48111 | K32: 5/7/2024 | L32: 7/12/2026 | M32: ? | N32: 300 test 1 | Q32: Removed, not in a relevant unit
A33: 22 | B33: 6 | E33: scrub oak | F33: Scrub oak | G33: 41.49095 | H33: -75.48082 | I33: 41.4904 | J33: -75.48111 | K33: 5/7/2024 | L33: 7/12/2026 | M33: ? | N33: 300 test 1 | Q33: Removed, not in a relevant unit
A34: 22 | B34: 6 | E34: sassafras | F34: Sass | G34: 41.49095 | H34: -75.48082 | I34: 41.4904 | J34: -75.48111 | K34: 5/7/2024 | L34: 7/12/2026 | M34: ? | N34: 300 test 1 | Q34: Removed, not in a relevant unit
A35: 22 | B35: 7 | E35: teaberry | F35: Teaberry | G35: 41.49095 | H35: -75.48082 | I35: 41.4904 | J35: -75.48111 | K35: 5/7/2024 | L35: 7/12/2026 | M35: ? | N35: 300 test 1 | Q35: Removed, not in a relevant unit
... A47: 22 | B47: 8 | E47: sweet fern | F47: Sweet fern | G47: 41.49095 | H47: -75.48082 | I47: 41.4904 | J47: -75.48111 | K47: 5/7/2024 | L47: 7/12/2026 | M47: ? | N47: 300 test 1 | Q47: Removed, not in a relevant unit
A48: 22 | B48: 8 | E48: Poacea species | F48: Grass species | G48: 41.49095 | H48: -75.48082 | I48: 41.4904 | J48: -75.48111 | K48: 5/7/2024 | L48: 7/12/2026 | M48: ? | N48: 300 test 1 | P48: decide on morpho | Q48: Removed, not in a relevant unit
A49: 22 | B49: 9 | E49: bracken fern | F49: Bracken | G49: 41.49095 | H49: -75.48082 | I49: 41.4904 | J49: -75.48111 | K49: 5/7/2024 | L49: 7/12/2026 | M49: ? | N49: 300 test 1 | Q49: Removed, not in a relevant unit
A50: 22 | B50: 9 | E50: black huckleberry | F50: Huck | G50: 41.49095 | H50: -75.48082 | I50: 41.4904 | J50: -75.48111 | K50: 5/7/2024 | L50: 7/12/2026 | M50: ? | N50: 300 test 1 | Q50: Removed, not in a relevant unit
A51: 22 | B51: 9 | E51: scrub oak | F51: Scrub oak | G51: 41.49095 | H51: -75.48082 | I51: 41.4904 | J51: -75.48111 | K51: 5/7/2024 | L51: 7/12/2026 | M51: ? | N51: 300 test 1 | Q51: Removed, not in a relevant unit
A52: 22 | B52: 9 | E52: sassafras | F52: Sassafras | G52: 41.49095 | H52: -75.48082 | I52: 41.4904 | J52: -75.48111 | K52: 5/7/2024 | L52: 7/12/2026 | M52: ? | N52: 300 test 1 | Q52: Removed, not in a relevant unit
A53: 22 | B53: 9 | E53: smooth witherod | F53: Viburnum nudum | G53: 41.49095 | H53: -75.48082 | I53: 41.4904 | J53: -75.48111 | K53: 5/7/2024 | L53: 7/12/2026 | M53: ? | N53: 300 test 1 | Q53: Removed, not in a relevant unit
A54: 22 | B54: 10 | E54: bracken fern | F54: Bracken | G54: 41.49095 | H54: -75.48082 | I54: 41.4904 | J54: -75.48111 | K54: 5/7/2024 | L54: 7/12/2026 | M54: ? | N54: 300 test 1 | Q54: Removed, not in a relevant unit
A55: 22 | B55: 10 | E55: black huckleberry | F55: Huck | G55: 41.49095 | H55: -75.48082 | I55: 41.4904 | J55: -75.48111 | K55: 5/7/2024 | L55: 7/12/2026 | M55: ? | N55: 300 test 1 | Q55: Removed, not in a relevant unit
...

Sheet pivot tables
C4: Row Labels | D4: Distinct Count of Transect #
C5: 0-1 | D5: 12
C6: 10+ | D6: 12
C7: 1-5 | D7: 12
C8: 5-10 | D8: 12
C9: Never | D9: 12
C10: Grand Total | D10: 59

Sheet Flora of PA
A1: Species | B1: TNRS Name | C1: Common Name | D1: Family | E1: USDA Status | F1: NewFamily | G1: Status | H1: Notes | I1: Phylomatic | J1: Genus | K1: Epithet3 | L1: Epithet 2 | M1: Epithet | N1: SSP | O1: SSP2 | P1: SSP3 | Q1: SSP4 | R1: SSP5
A2: Abies balsamea | B2: Abies balsamea | C2: Balsam fir | D2: Pinaceae | E2: =VLOOKUP(A2,[1]USDAPLANTS!C$2:D$32889,2) -> L48(N)CAN(N)SPM(N) | F2: Pinaceae | G2: native | I2: pinaceae/abies/Abies_balsamea | J2: Abies | K2: balsamea | L2: =M2 -> balsamea | M2: balsamea
A3: Abies concolor | B3: Abies concolor | C3: White fir | D3: Pinaceae | E3: =VLOOKUP(A3,[1]USDAPLANTS!C$2:D$32889,2) -> L48(N) | F3: Pinaceae | G3: native | I3: pinaceae/abies/Abies_concolor | J3: Abies | K3: concolor | L3: =M3 -> concolor | M3: concolor
A4: Abutilon theophrasti | B4: Abutilon theophrasti | C4: Butter-print | D4: Malvaceae | E4: =VLOOKUP(A4,[1]USDAPLANTS!C$2:D$32889,2) -> L48(I)CAN(I) | F4: Malvaceae | G4: introduced | I4: malvaceae/abutilon/Abutilon_theophrasti | J4: Abutilon | K4: theophrasti | L4: =M4 -> theophrasti | M4: theophrasti
A5: Acalypha deamii | B5: Acalypha deamii | C5: Deam's threeseed mercury | D5: Euphorbiaceae | E5: =VLOOKUP(A5,[1]USDAPLANTS!C$2:D$32889,2) -> L48(N) | F5: Euphorbiaceae | G5: native | I5: euphorbiaceae/acalypha/Acalypha_deamii | J5: Acalypha | K5: deamii | L5: =M5 -> deamii | M5: deamii
A6: Acalypha gracilens | B6: Acalypha gracilens | C6: Slender mercury | D6: Euphorbiaceae | E6: =VLOOKUP(A6,[1]USDAPLANTS!C$2:D$32889,2) -> L48(N) | F6: Euphorbiaceae | G6: native | I6: euphorbiaceae/acalypha/Acalypha_gracilens | J6: Acalypha | K6: gracilens | L6: =M6 -> gracilens | M6: gracilens
A7: Acalypha rhomboidea | B7: Acalypha rhomboidea | C7: Common threeseed mercury | D7: Euphorbiaceae | E7: =VLOOKUP(A7,[1]USDAPLANTS!C$2:D$32889,2) -> L48(N)CAN(N) | F7: Euphorbiaceae | G7: native | I7: euphorbiaceae/acalypha/Acalypha_rhomboidea | J7: Acalypha | K7: rhomboidea | L7: =M7 -> rhomboidea | M7: rhomboidea
A8: Acalypha virginica | B8: Acalypha virginica | C8: Virginia threeseed mercury | D8: Euphorbiaceae | E8: =VLOOKUP(A8,[1]USDAPLANTS!C$2:D$32889,2) -> L48(N) | F8: Euphorbiaceae | G8: native | I8: euphorbiaceae/acalypha/Acalypha_virginica | J8: Acalypha | K8: virginica | L8: =M8 -> virginica | M8: virginica
A9: Acanthopanax sieboldianus | B9: Acanthopanax sieboldianus | C9: Fiveleaf aralia | D9: Araliaceae | E9: =VLOOKUP(A9,[1]USDAPLANTS!C$2:D$32889,2) -> L48(N) | F9: Araliaceae | G9: native | I9: araliaceae/acanthopanax/Acanthopanax_sieboldianus | J9: Acanthopanax | K9: sieboldianus | L9: =M9 -> sieboldianus | M9: sieboldianus
A10: Acer campestre | B10: Acer campestre | C10: Hedge maple | D10: Sapindaceae | E10: =VLOOKUP(A10,[1]USDAPLANTS!C$2:D$32889,2) -> L48(I)CAN(I) | F10: Sapindaceae | G10: introduced | I10: sapindaceae/acer/Acer_campestre | J10: Acer | K10: campestre | L10: =M10 -> campestre | M10: campestre
A11: Acer ginnala | B11: Acer ginnala | C11: Amur maple | D11: Sapindaceae | E11: =VLOOKUP(A11,[1]USDAPLANTS!C$2:D$32889,2) -> L48(I)CAN(I) | F11: Sapindaceae | G11: introduced | I11: sapindaceae/acer/Acer_ginnala | J11: Acer | K11: ginnala | L11: =M11 -> ginnala | M11: ginnala
A12: Acer negundo | B12: Acer negundo | C12: Box-elder | D12: Sapindaceae | E12: =VLOOKUP(A12,[1]USDAPLANTS!C$2:D$32889,2) -> L48(N)CAN(N) | F12: Sapindaceae | G12: native | I12: sapindaceae/acer/Acer_negundo | J12: Acer | K12: negundo | L12: =M12 -> negundo | M12: negundo
A13: Acer nigrum | B13: Acer nigrum | C13: Black maple | D13: Sapindaceae | E13: =VLOOKUP(A13,[1]USDAPLANTS!C$2:D$32889,2) -> L48(N)CAN(N) | F13: Sapindaceae | G13: native | I13: sapindaceae/acer/Acer_nigrum | J13: Acer | K13: nigrum | L13: =M13 -> nigrum | M13: nigrum
... A21: Acer spicatum | B21: Acer spicatum | C21: Mountain maple | D21: Sapindaceae | E21: =VLOOKUP(A21,[1]USDAPLANTS!C$2:D$32889,2) -> L48(N)CAN(N)SPM(N) | F21: Sapindaceae | G21: native | I21: sapindaceae/acer/Acer_spicatum | J21: Acer | K21: spicatum | L21: =M21 -> spicatum | M21: spicatum
A22: Achillea millefolium | B22: Achillea millefolium | C22: Common yarrow | D22: Asteraceae | E22: =VLOOKUP(A22,[1]USDAPLANTS!C$2:D$32889,2) -> L48(I,N)AK(N)HI(I)CAN(NI)GL(N)SPM(NI) | F22: Asteraceae | G22: introduced | H22: ambig on USDA, decided from Plants of PA | I22: asteraceae/achillea/Achillea_millefolium | J22: Achillea | K22: millefolium | L22: =M22 -> millefolium | M22: millefolium
A23: Achillea ptarmica | B23: Achillea ptarmica | C23: Sneezeweed | D23: Asteraceae | E23: =VLOOKUP(A23,[1]USDAPLANTS!C$2:D$32889,2) -> L48(I)AK(I)CAN(I)GL(I)SPM(I) | F23: Asteraceae | G23: introduced | I23: asteraceae/achillea/Achillea_ptarmica | J23: Achillea | K23: ptarmica | L23: =M23 -> ptarmica | M23: ptarmica
A24: Acinos arvensis | B24: Acinos arvensis | C24: Mother-of-thyme | D24: Lamiaceae | E24: =VLOOKUP(A24,[1]USDAPLANTS!C$2:D$32889,2) -> L48(I)CAN(I) | F24: Lamiaceae | G24: introduced | I24: lamiaceae/acinos/Acinos_arvensis | J24: Acinos | K24: arvensis | L24: =M24 -> arvensis | M24: arvensis
A25: Aconitum reclinatum | B25: Aconitum reclinatum | C25: White monkshood | D25: Ranunculaceae | E25: =VLOOKUP(A25,[1]USDAPLANTS!C$2:D$32889,2) -> L48(N) | F25: Ranunculaceae | G25: native | I25: ranunculaceae/aconitum/Aconitum_reclinatum | J25: Aconitum | K25: reclinatum | L25: =M25 -> reclinatum | M25: reclinatum
A26: Aconitum uncinatum | B26: Aconitum uncinatum | C26: Blue monkshood | D26: Ranunculaceae | E26: =VLOOKUP(A26,[1]USDAPLANTS!C$2:D$32889,2) -> L48(N) | F26: Ranunculaceae | G26: native | I26: ranunculaceae/aconitum/Aconitum_uncinatum | J26: Aconitum | K26: uncinatum | L26: =M26 -> uncinatum | M26: uncinatum
A27: Acorus americanus | B27: Acorus americanus | C27: Sweetflag | D27: Acoraceae | E27: =VLOOKUP(A27,[1]USDAPLANTS!C$2:D$32889,2) -> L48(N)AK(N)CAN(N) | F27: Acoraceae | G27: native | I27: acoraceae/acorus/Acorus_americanus | J27: Acorus | K27: americanus | L27: =M27 -> americanus | M27: americanus
A28: Acorus calamus | B28: Acorus calamus | C28: Calamus | D28: Acoraceae | E28: =VLOOKUP(A28,[1]USDAPLANTS!C$2:D$32889,2) -> L48(I)CAN(I) | F28: Acoraceae | G28: introduced | I28: acoraceae/acorus/Acorus_calamus | J28: Acorus | K28: calamus | L28: =M28 -> calamus | M28: calamus
A29: Actaea pachypoda | B29: Actaea pachypoda | C29: Doll's-eyes | D29: Ranunculaceae | E29: =VLOOKUP(A29,[1]USDAPLANTS!C$2:D$32889,2) -> L48(N)CAN(N) | F29: Ranunculaceae | G29: native | I29: ranunculaceae/actaea/Actaea_pachypoda | J29: Actaea | K29: pachypoda | L29: =M29 -> pachypoda | M29: pachypoda
A30: Actaea podocarpa | B30: Actaea podocarpa | C30: American bugbane | D30: Ranunculaceae | E30: =VLOOKUP(A30,[1]USDAPLANTS!C$2:D$32889,2) -> L48(N) | F30: Ranunculaceae | G30: native | I30: ranunculaceae/actaea/Actaea_podocarpa | J30: Actaea | K30: podocarpa | L30: =M30 -> podocarpa | M30: podocarpa
A31: Actaea racemosa | B31: Actaea racemosa | C31: Black snakeroot | D31: Ranunculaceae | E31: =VLOOKUP(A31,[1]USDAPLANTS!C$2:D$32889,2) -> L48(N)CAN(N) | F31: Ranunculaceae | G31: native | I31: ranunculaceae/actaea/Actaea_racemosa | J31: Actaea | K31: racemosa | L31: =M31 -> racemosa | M31: racemosa
A32: Actaea rubra | B32: Actaea rubra | C32: Red baneberry | D32: Ranunculaceae | E32: =VLOOKUP(A32,[1]USDAPLANTS!C$2:D$32889,2) -> L48(N)AK(N)CAN(N) | F32: Ranunculaceae | G32: native | I32: ranunculaceae/actaea/Actaea_rubra | J32: Actaea | K32: rubra | L32: =M32 -> rubra | M32: rubra
A33: Actinidia arguta | B33: Actinidia arguta | C33: Bower actinidia | D33: Actinidiaceaae | E33: =VLOOKUP(A33,[1]USDAPLANTS!C$2:D$32889,2) -> L48(I) | F33: Actinidiaceaae | G33: introduced | I33: actinidiaceaae/actinidia/Actinidia_arguta | J33: Actinidia | K33: arguta | L33: =M33 -> arguta | M33: arguta
A34: Adiantum aleuticum | B34: Adiantum aleuticum | C34: Aleutian maidenhair | D34: Polypodiaceae | E34: =VLOOKUP(A34,[1]USDAPLANTS!C$2:D$32889,2) -> L48(N)AK(N)CAN(N) | F34: Polypodiaceae | G34: native | I34: polypodiaceae/adiantum/Adiantum_aleuticum | J34: Adiantum | K34: aleuticum | L34: =M34 -> aleuticum | M34: aleuticum
... A52: Agastache scrophulariifolia | B52: Agastache scrophulariifolia | C52: Purple giant-hyssop | D52: Lamiaceae | E52: =VLOOKUP(A52,[1]USDAPLANTS!C$2:D$32889,2) -> L48(N)CAN(N) | F52: Lamiaceae | G52: native | I52: lamiaceae/agastache/Agastache_scrophulariifolia | J52: Agastache | K52: scrophulariifolia | L52: =M52 -> scrophulariifolia | M52: scrophulariifolia
A53: Ageratina altissima var. altissima | B53: Ageratina altissima var. altissima | C53: White-snakeroot | D53: Asteraceae | E53: =VLOOKUP(A53,[1]USDAPLANTS!C$2:D$32889,2) -> L48(N)CAN(N) | F53: Asteraceae | G53: native | I53: asteraceae/ageratina/Ageratina_altissima var. altissima | J53: Ageratina | K53: altissima var. altissima | L53: =M53&" "&N53&" "&O53 -> altissima var. altissima | M53: altissima | N53: var. | O53: altissima
A54: Ageratina aromatica | B54: Ageratina aromatica | C54: Small-leaved white-snakeroot | D54: Asteraceae | E54: =VLOOKUP(A54,[1]USDAPLANTS!C$2:D$32889,2) -> L48(N) | F54: Asteraceae | G54: native | I54: asteraceae/ageratina/Ageratina_aromatica | J54: Ageratina | K54: aromatica | L54: =M54 -> aromatica | M54: aromatica
A55: Agrimonia gryposepala | B55: Agrimonia gryposepala | C55: Agrimony | D55: Rosaceae | E55: =VLOOKUP(A55,[1]USDAPLANTS!C$2:D$32889,2) -> L48(I) | F55: Rosaceae | G55: introduced | I55: rosaceae/agrimonia/Agrimonia_gryposepala | J55: Agrimonia | K55: gryposepala | L55: =M55 -> gryposepala | M55: gryposepala
A56: Agrimonia microcarpa | B56: Agrimonia microcarpa | C56: Small-fruited agrimony | D56: Rosaceae | E56: =VLOOKUP(A56,[1]USDAPLANTS!C$2:D$32889,2) -> L48(I) | F56: Rosaceae | G56: introduced | I56: rosaceae/agrimonia/Agrimonia_microcarpa | J56: Agrimonia | K56: microcarpa | L56: =M56 -> microcarpa | M56: microcarpa
A57: Agrimonia parviflora | B57: Agrimonia parviflora | C57: Southern agrimony | D57: Rosaceae | E57: =VLOOKUP(A57,[1]USDAPLANTS!C$2:D$32889,2) -> L48(I) | F57: Rosaceae | G57: introduced | I57: rosaceae/agrimonia/Agrimonia_parviflora | J57: Agrimonia | K57: parviflora | L57: =M57 -> parviflora | M57: parviflora
A58: Agrimonia pubescens | B58: Agrimonia pubescens | C58: Downy agrimony | D58: Rosaceae | E58: =VLOOKUP(A58,[1]USDAPLANTS!C$2:D$32889,2) -> L48(I) | F58: Rosaceae | G58: introduced | I58: rosaceae/agrimonia/Agrimonia_pubescens | J58: Agrimonia | K58: pubescens | L58: =M58 -> pubescens | M58: pubescens
A59: Agrimonia rostellata | B59: Agrimonia rostellata | C59: Woodland agrimony | D59: Rosaceae | E59: =VLOOKUP(A59,[1]USDAPLANTS!C$2:D$32889,2) -> L48(I) | F59: Rosaceae | G59: introduced | I59: rosaceae/agrimonia/Agrimonia_rostellata | J59: Agrimonia | K59: rostellata | L59: =M59 -> rostellata | M59: rostellata
A60: Agrimonia striata | B60: Agrimonia striata | C60: Roadside agrimony | D60: Rosaceae | E60: =VLOOKUP(A60,[1]USDAPLANTS!C$2:D$32889,2) -> L48(I) | F60: Rosaceae | G60: introduced | I60: rosaceae/agrimonia/Agrimonia_striata | J60: Agrimonia | K60: striata | L60: =M60 -> striata | M60: striata
A61: Agrostemma githago | B61: Agrostemma githago | C61: Corn cockle | D61: Caryophyllaceae | E61: =VLOOKUP(A61,[1]USDAPLANTS!C$2:D$32889,2) -> L48(I)AK(I)CAN(I) | F61: Caryophyllaceae | G61: introduced | I61: caryophyllaceae/agrostemma/Agrostemma_githago | J61: Agrostemma | K61: githago | L61: =M61 -> githago | M61: githago
A62: Agrostis altissima | B62: Agrostis altissima | C62: Tall bentgrass | D62: Poaceae | E62: =VLOOKUP(A62,[1]USDAPLANTS!C$2:D$32889,2) -> L48(N)AK(N)CAN(N) | F62: Poaceae | G62: native | I62: poaceae/agrostis/Agrostis_altissima | J62: Agrostis | K62: altissima | L62: =M62 -> altissima | M62: altissima
A63: Agrostis canina | B63: Agrostis canina | C63: Brown bent | D63: Poaceae | E63: =VLOOKUP(A63,[1]USDAPLANTS!C$2:D$32889,2) -> L48(N)HI(I)CAN(W)GL(I)SPM(W) | F63: Poaceae | G63: native | I63: poaceae/agrostis/Agrostis_canina | J63: Agrostis | K63: canina | L63: =M63 -> canina | M63: canina
A64: Agrostis capillaris | B64: Agrostis capillaris | C64: Rhode Island bent | D64: Poaceae | E64: =VLOOKUP(A64,[1]USDAPLANTS!C$2:D$32889,2) -> L48(I)AK(I)HI(I)CAN(I)GL(I)SPM(I) | F64: Poaceae | G64: introduced | I64: poaceae/agrostis/Agrostis_capillaris | J64: Agrostis | K64: capillaris | L64: =M64 -> capillaris | M64: capillaris
...
